<?xml version="1.0" ?>
<!-- =================================================================================== -->
<!-- |    This document was autogenerated by xacro from /home/harshit/arm_vla_ws/src/akabot_description/urdf/akabot.urdf.xacro | -->
<!-- |    EDITING THIS FILE BY HAND IS NOT RECOMMENDED                                 | -->
<!-- =================================================================================== -->
<robot name="akabot">
  <!-- World link -->
  <link name="world"/>
  <!-- Fix base_link to Gazebo world -->
  <joint name="fixed" type="fixed">
    <parent link="world"/>
    <child link="base_link"/>
  </joint>
  <!-- Base link  -->
  <link name="base_link"/>
  <joint name="base_plate_joint" type="fixed">
    <parent link="base_link"/>
    <child link="base_plate"/>
    <origin xyz="0 0 0"/>
  </joint>
  <!-- Base plate -->
  <link name="base_plate">
    <visual>
      <origin xyz="0 0 0.001"/>
      <geometry>
        <mesh filename="package://akabot_description/meshes/base_cylinder.stl" scale="0.00001 0.00001 0.00001"/>
      </geometry>
      <material name="black">
        <color rgba="0 0 0 1"/>
      </material>
    </visual>
    <collision>
      <origin xyz="0 0 0.001"/>
      <geometry>
        <mesh filename="package://akabot_description/meshes/base_cylinder.stl" scale="0.00001 0.00001 0.00001"/>
      </geometry>
    </collision>
    <inertial>
      <origin rpy="0 0 0" xyz="0 0 0"/>
      <mass value="0.527"/>
      <inertia ixx="0.0006696413333333334" ixy="0.0" ixz="0.0" iyy="0.002148798583333333" iyz="0.0" izz="0.002580938583333333"/>
    </inertial>
  </link>
  <joint name="top_plate_joint" type="revolute">
    <parent link="base_plate"/>
    <child link="top_plate"/>
    <origin rpy="0 0 1.5" xyz="0 0 0.048"/>
    <axis xyz="0 0 1"/>
    <limit effort="1000.0" lower="1.56" upper="4.68" velocity="1.0"/>
  </joint>
  <!-- Top plate -->
  <link name="top_plate">
    <visual>
      <origin xyz="0 0 0"/>
      <geometry>
        <mesh filename="package://akabot_description/meshes/top_plate.stl" scale="0.0001 0.0001 0.0001"/>
      </geometry>
      <material name="black"/>
    </visual>
    <collision>
      <geometry>
        <mesh filename="package://akabot_description/meshes/top_plate.stl" scale="0.0001 0.0001 0.0001"/>
      </geometry>
    </collision>
    <inertial>
      <origin rpy="0 0 0" xyz="0 0 0"/>
      <mass value="0.115"/>
      <inertia ixx="8.700708333333333e-05" ixy="0.0" ixz="0.0" iyy="8.700708333333333e-05" iyz="0.0" izz="0.0001739375"/>
    </inertial>
  </link>
  <joint name="lower_arm_joint" type="revolute">
    <parent link="top_plate"/>
    <child link="lower_arm"/>
    <origin xyz="0 0.019 0.028"/>
    <axis xyz="1 0 0"/>
    <limit effort="1000.0" lower="0.0" upper="3.12" velocity="1.0"/>
  </joint>
  <!-- Lower arm -->
  <link name="lower_arm">
    <visual>
      <geometry>
        <mesh filename="package://akabot_description/meshes/lower_arm.stl" scale="0.0001 0.0001 0.0001"/>
      </geometry>
      <material name="black"/>
    </visual>
    <collision>
      <origin xyz="0 0 0"/>
      <geometry>
        <mesh filename="package://akabot_description/meshes/lower_arm.stl" scale="0.0001 0.0001 0.0001"/>
      </geometry>
    </collision>
    <inertial>
      <origin rpy="0 0 0" xyz="0 0 0"/>
      <mass value="0.047"/>
      <inertia ixx="1.4730583333333334e-05" ixy="0.0" ixz="0.0" iyy="6.863958333333334e-05" iyz="0.0" izz="7.847433333333333e-05"/>
    </inertial>
  </link>
  <joint name="upper_arm_joint" type="revolute">
    <parent link="lower_arm"/>
    <child link="upper_arm"/>
    <origin xyz="-0.025 0.1 0"/>
    <axis xyz="1 0 0"/>
    <limit effort="1000.0" lower="-1.7" upper="1.7" velocity="1.0"/>
  </joint>
  <!-- Upper arm -->
  <link name="upper_arm">
    <visual>
      <origin rpy="0 1.59 0" xyz="0 0 0"/>
      <geometry>
        <mesh filename="package://akabot_description/meshes/upper_arm.stl" scale="0.0001 0.0001 0.0001"/>
      </geometry>
      <material name="black"/>
    </visual>
    <collision>
      <origin rpy="0 1.59 0" xyz="0 0 0"/>
      <geometry>
        <mesh filename="package://akabot_description/meshes/upper_arm.stl" scale="0.0001 0.0001 0.0001"/>
      </geometry>
    </collision>
    <inertial>
      <origin rpy="0 0 0" xyz="0 0 0"/>
      <mass value="0.105"/>
      <inertia ixx="1.6808749999999997e-05" ixy="0.0" ixz="0.0" iyy="0.0003049375" iyz="0.0" izz="0.00031080874999999997"/>
    </inertial>
  </link>
  <joint name="wrist_joint" type="revolute">
    <parent link="upper_arm"/>
    <child link="wrist"/>
    <origin xyz="0.011 0.125 0"/>
    <axis xyz="1 0 0"/>
    <limit effort="1000.0" lower="-1.7" upper="1.7" velocity="1.0"/>
  </joint>
  <!-- Wrist -->
  <link name="wrist">
    <visual>
      <geometry>
        <mesh filename="package://akabot_description/meshes/wrist.stl" scale="0.0001 0.0001 0.0001"/>
      </geometry>
      <material name="black"/>
    </visual>
    <collision>
      <origin rpy="0 0 0" xyz="0 0 0"/>
      <geometry>
        <mesh filename="package://akabot_description/meshes/wrist.stl" scale="0.0001 0.0001 0.0001"/>
      </geometry>
    </collision>
    <inertial>
      <origin rpy="0 0 0" xyz="0 0 0"/>
      <mass value="0.082"/>
      <inertia ixx="2.6472333333333337e-05" ixy="0.0" ixz="0.0" iyy="3.314166666666667e-05" iyz="0.0" izz="5.107233333333334e-05"/>
    </inertial>
  </link>
  <joint name="claw_base_joint" type="revolute">
    <axis xyz="0 1 0"/>
    <limit effort="1000.0" lower="-3.17" upper="0.0" velocity="1.0"/>
    <parent link="wrist"/>
    <child link="claw_base"/>
    <origin xyz="0 0.063 0"/>
  </joint>
  <!-- Claw base -->
  <link name="claw_base">
    <visual>
      <origin rpy="0 3.18 0" xyz="0 0 0"/>
      <geometry>
        <mesh filename="package://akabot_description/meshes/claw_base.stl" scale="0.0001 0.0001 0.0001"/>
      </geometry>
      <material name="white">
        <color rgba="1 1 1 1"/>
      </material>
    </visual>
    <collision>
      <origin rpy="0 3.18 0" xyz="0 0 0"/>
      <geometry>
        <mesh filename="package://akabot_description/meshes/claw_base.stl" scale="0.0001 0.0001 0.0001"/>
      </geometry>
    </collision>
    <inertial>
      <origin rpy="0 0 0" xyz="0 0 0"/>
      <mass value="0.079"/>
      <inertia ixx="1.7939583333333337e-05" ixy="0.0" ixz="0.0" iyy="3.373958333333334e-05" iyz="0.0" izz="4.8716666666666674e-05"/>
    </inertial>
  </link>
  <joint name="right_claw_joint" type="revolute">
    <parent link="claw_base"/>
    <child link="right_claw"/>
    <origin rpy="0 0 -0.31" xyz="0.011 0.0335 0.00155"/>
    <axis xyz="0 0 1"/>
    <limit effort="1000.0" lower="-0.5" upper="0.0" velocity="1.0"/>
  </joint>
  <!-- Right claw  -->
  <link name="right_claw">
    <visual>
      <origin rpy="0 0 0" xyz="0 0 0"/>
      <geometry>
        <mesh filename="package://akabot_description/meshes/right_claw.stl" scale="0.0001 0.0001 0.0001"/>
      </geometry>
      <material name="white"/>
    </visual>
    <collision>
      <origin rpy="0 0 0" xyz="0 0 0"/>
      <geometry>
        <mesh filename="package://akabot_description/meshes/right_claw.stl" scale="0.0001 0.0001 0.0001"/>
      </geometry>
    </collision>
    <inertial>
      <origin rpy="0 0 0" xyz="0 0 0"/>
      <mass value="0.019"/>
      <inertia ixx="3.8633333333333336e-07" ixy="0.0" ixz="0.0" iyy="1.6061333333333335e-05" iyz="0.0" izz="1.5991666666666668e-05"/>
    </inertial>
  </link>
  <!-- Left claw -->
  <link name="left_claw">
    <visual>
      <origin rpy="0 0 0" xyz="0 0 0"/>
      <geometry>
        <mesh filename="package://akabot_description/meshes/left_claw.stl" scale="0.0001 0.0001 0.0001"/>
      </geometry>
      <material name="white"/>
    </visual>
    <collision>
      <origin rpy="0 0 0" xyz="0 0 0"/>
      <geometry>
        <mesh filename="package://akabot_description/meshes/left_claw.stl" scale="0.0001 0.0001 0.0001"/>
      </geometry>
    </collision>
    <inertial>
      <origin rpy="0 0 0" xyz="0 0 0"/>
      <mass value="0.019"/>
      <inertia ixx="3.8633333333333336e-07" ixy="0.0" ixz="0.0" iyy="1.6061333333333335e-05" iyz="0.0" izz="1.5991666666666668e-05"/>
    </inertial>
  </link>
  <joint name="left_claw_joint" type="revolute">
    <parent link="claw_base"/>
    <child link="left_claw"/>
    <origin rpy="0 0 0.22" xyz="-0.016 0.030 0"/>
    <axis xyz="0 0 1"/>
    <limit effort="1000.0" lower="0.0" upper="0.5" velocity="1.0"/>
    <mimic joint="right_claw_joint" multiplier="-1" offset="0"/>
  </joint>
  <link name="camera_pole_link">
    <visual>
      <origin rpy="0 0 0" xyz="0 0 0.4"/>
      <geometry>
        <cylinder length="0.8" radius="0.015"/>
      </geometry>
      <material name="pole_grey">
        <color rgba="0.2 0.2 0.2 1"/>
      </material>
    </visual>
    <collision>
      <origin rpy="0 0 0" xyz="0 0 0.4"/>
      <geometry>
        <cylinder length="0.8" radius="0.015"/>
      </geometry>
    </collision>
    <inertial>
      <mass value="1.0"/>
      <inertia ixx="0.01" ixy="0.0" ixz="0.0" iyy="0.01" iyz="0.0" izz="0.01"/>
    </inertial>
  </link>
  <joint name="pole_to_base_joint" type="fixed">
    <parent link="base_plate"/>
    <child link="camera_pole_link"/>
    <origin rpy="0 0 0" xyz="0.3 0.4 0.0"/>
  </joint>
  <link name="tf_camera_link">
    <visual>
      <origin rpy="0 0 0" xyz="0 0 0"/>
      <geometry>
        <box size="0.02 0.05 0.02"/>
      </geometry>
      <material name="camera_black">
        <color rgba="0 0 0 1"/>
      </material>
    </visual>
    <collision>
      <origin rpy="0 0 0" xyz="0 0 0"/>
      <geometry>
        <box size="0.02 0.05 0.02"/>
      </geometry>
    </collision>
    <inertial>
      <mass value="0.05"/>
      <inertia ixx="0.0001" ixy="0.0" ixz="0.0" iyy="0.0001" iyz="0.0" izz="0.0001"/>
    </inertial>
  </link>
  <joint name="tf_camera_joint" type="fixed">
    <parent link="camera_pole_link"/>
    <child link="tf_camera_link"/>
    <origin rpy="3.24 7.54 -1.57" xyz="0 -0.1 0.8"/>
  </joint>
  <link name="tf_camera_optical_link"/>
  <joint name="tf_camera_optical_joint" type="fixed">
    <parent link="tf_camera_link"/>
    <child link="tf_camera_optical_link"/>
    <origin rpy="-1.5707963267948966 0 -1.5707963267948966" xyz="0 0 0"/>
  </joint>
  <gazebo reference="tf_camera_link">
    <sensor name="tf_camera" type="camera">
      <pose>0 0 0 0 0 0</pose>
      <always_on>1</always_on>
      <update_rate>30</update_rate>
      <visualize>true</visualize>
      <topic>tf_camera/image_raw</topic>
      <camera>
        <horizontal_fov>1.2217</horizontal_fov>
        <image>
          <width>640</width>
          <height>480</height>
          <format>R8G8B8</format>
        </image>
        <clip>
          <near>0.02</near>
          <far>5.0</far>
        </clip>
        <noise>
          <type>gaussian</type>
          <mean>0.0</mean>
          <stddev>0.007</stddev>
        </noise>
      </camera>
    </sensor>
  </gazebo>
  <!-- End Effector Camera (Small USB Camera) -->
  <link name="ee_camera_link">
    <visual>
      <origin rpy="0 0 0" xyz="0 0 0"/>
      <geometry>
        <box size="0.02 0.03 0.015"/>
      </geometry>
      <material name="camera_grey">
        <color rgba="0.3 0.3 0.3 1"/>
      </material>
    </visual>
    <collision>
      <origin rpy="0 0 0" xyz="0 0 0"/>
      <geometry>
        <box size="0.02 0.03 0.015"/>
      </geometry>
    </collision>
    <inertial>
      <mass value="0.01"/>
      <inertia ixx="0.0001" ixy="0.0" ixz="0.0" iyy="0.0001" iyz="0.0" izz="0.0001"/>
    </inertial>
  </link>
  <!-- Mount camera on claw_base, pointing LEFT -->
  <joint name="ee_camera_joint" type="fixed">
    <parent link="claw_base"/>
    <child link="ee_camera_link"/>
    <origin rpy="0 0 1.5707963267948966" xyz="0.001 0.025 0.02"/>
  </joint>
  <!-- Optical frame for the camera -->
  <link name="ee_camera_optical_link"/>
  <joint name="ee_camera_optical_joint" type="fixed">
    <parent link="ee_camera_link"/>
    <child link="ee_camera_optical_link"/>
    <origin rpy="1.5707963267948966 0 1.5707963267948966" xyz="0 0 0"/>
  </joint>
  <!-- ==========================================
       GAZEBO SIM (IGNITION) CAMERA SENSOR
       This uses the NEW Gazebo plugin system
       ========================================== -->
  <gazebo reference="ee_camera_link">
    <sensor name="ee_camera" type="camera">
      <pose>0 0 0  0 0 0</pose>
      <always_on>1</always_on>
      <update_rate>30</update_rate>
      <visualize>true</visualize>
      <topic>ee_camera</topic>
      <camera>
        <horizontal_fov>1.2217</horizontal_fov>
        <!-- 70 degrees -->
        <image>
          <width>640</width>
          <height>480</height>
          <format>R8G8B8</format>
        </image>
        <clip>
          <near>0.02</near>
          <far>3.0</far>
        </clip>
        <noise>
          <type>gaussian</type>
          <mean>0.0</mean>
          <stddev>0.007</stddev>
        </noise>
      </camera>
    </sensor>
  </gazebo>
</robot>
